[2025-04-10T22:46:30.688+0000] {taskinstance.py:1157} INFO - Dependencies all met for dep_context=non-requeueable deps ti=<TaskInstance: minio_pipeline_dag.transform_using_nifi manual__2025-04-10T22:46:19.343282+00:00 [queued]>
[2025-04-10T22:46:30.696+0000] {taskinstance.py:1157} INFO - Dependencies all met for dep_context=requeueable deps ti=<TaskInstance: minio_pipeline_dag.transform_using_nifi manual__2025-04-10T22:46:19.343282+00:00 [queued]>
[2025-04-10T22:46:30.696+0000] {taskinstance.py:1359} INFO - Starting attempt 1 of 2
[2025-04-10T22:46:30.707+0000] {taskinstance.py:1380} INFO - Executing <Task(_PythonDecoratedOperator): transform_using_nifi> on 2025-04-10 22:46:19.343282+00:00
[2025-04-10T22:46:30.713+0000] {standard_task_runner.py:57} INFO - Started process 413 to run task
[2025-04-10T22:46:30.716+0000] {standard_task_runner.py:84} INFO - Running: ['***', 'tasks', 'run', 'minio_pipeline_dag', 'transform_using_nifi', 'manual__2025-04-10T22:46:19.343282+00:00', '--job-id', '17', '--raw', '--subdir', 'DAGS_FOLDER/app.py', '--cfg-path', '/tmp/tmpcfk_2re4']
[2025-04-10T22:46:30.718+0000] {standard_task_runner.py:85} INFO - Job 17: Subtask transform_using_nifi
[2025-04-10T22:46:30.751+0000] {task_command.py:415} INFO - Running <TaskInstance: minio_pipeline_dag.transform_using_nifi manual__2025-04-10T22:46:19.343282+00:00 [running]> on host 8fadf2d6906b
[2025-04-10T22:46:30.808+0000] {taskinstance.py:1660} INFO - Exporting env vars: AIRFLOW_CTX_DAG_OWNER='data_team' AIRFLOW_CTX_DAG_ID='minio_pipeline_dag' AIRFLOW_CTX_TASK_ID='transform_using_nifi' AIRFLOW_CTX_EXECUTION_DATE='2025-04-10T22:46:19.343282+00:00' AIRFLOW_CTX_TRY_NUMBER='1' AIRFLOW_CTX_DAG_RUN_ID='manual__2025-04-10T22:46:19.343282+00:00'
[2025-04-10T22:46:30.813+0000] {logging_mixin.py:151} INFO - Error triggering NiFi processor group: HTTPConnectionPool(host='nifi', port=8080): Max retries exceeded with url: /nifi-api/flow/process-groups/21c8e227-0196-1000-55b1-efeba7bbe5dc/run-status (Caused by NewConnectionError('<urllib3.connection.HTTPConnection object at 0x79f37b2bd280>: Failed to establish a new connection: [Errno 111] Connection refused'))
[2025-04-10T22:46:30.813+0000] {taskinstance.py:1935} ERROR - Task failed with exception
Traceback (most recent call last):
  File "/home/airflow/.local/lib/python3.8/site-packages/urllib3/connection.py", line 174, in _new_conn
    conn = connection.create_connection(
  File "/home/airflow/.local/lib/python3.8/site-packages/urllib3/util/connection.py", line 95, in create_connection
    raise err
  File "/home/airflow/.local/lib/python3.8/site-packages/urllib3/util/connection.py", line 85, in create_connection
    sock.connect(sa)
ConnectionRefusedError: [Errno 111] Connection refused

During handling of the above exception, another exception occurred:

Traceback (most recent call last):
  File "/home/airflow/.local/lib/python3.8/site-packages/urllib3/connectionpool.py", line 714, in urlopen
    httplib_response = self._make_request(
  File "/home/airflow/.local/lib/python3.8/site-packages/urllib3/connectionpool.py", line 415, in _make_request
    conn.request(method, url, **httplib_request_kw)
  File "/home/airflow/.local/lib/python3.8/site-packages/urllib3/connection.py", line 244, in request
    super(HTTPConnection, self).request(method, url, body=body, headers=headers)
  File "/usr/local/lib/python3.8/http/client.py", line 1256, in request
    self._send_request(method, url, body, headers, encode_chunked)
  File "/usr/local/lib/python3.8/http/client.py", line 1302, in _send_request
    self.endheaders(body, encode_chunked=encode_chunked)
  File "/usr/local/lib/python3.8/http/client.py", line 1251, in endheaders
    self._send_output(message_body, encode_chunked=encode_chunked)
  File "/usr/local/lib/python3.8/http/client.py", line 1011, in _send_output
    self.send(msg)
  File "/usr/local/lib/python3.8/http/client.py", line 951, in send
    self.connect()
  File "/home/airflow/.local/lib/python3.8/site-packages/urllib3/connection.py", line 205, in connect
    conn = self._new_conn()
  File "/home/airflow/.local/lib/python3.8/site-packages/urllib3/connection.py", line 186, in _new_conn
    raise NewConnectionError(
urllib3.exceptions.NewConnectionError: <urllib3.connection.HTTPConnection object at 0x79f37b2bd280>: Failed to establish a new connection: [Errno 111] Connection refused

During handling of the above exception, another exception occurred:

Traceback (most recent call last):
  File "/home/airflow/.local/lib/python3.8/site-packages/requests/adapters.py", line 486, in send
    resp = conn.urlopen(
  File "/home/airflow/.local/lib/python3.8/site-packages/urllib3/connectionpool.py", line 798, in urlopen
    retries = retries.increment(
  File "/home/airflow/.local/lib/python3.8/site-packages/urllib3/util/retry.py", line 592, in increment
    raise MaxRetryError(_pool, url, error or ResponseError(cause))
urllib3.exceptions.MaxRetryError: HTTPConnectionPool(host='nifi', port=8080): Max retries exceeded with url: /nifi-api/flow/process-groups/21c8e227-0196-1000-55b1-efeba7bbe5dc/run-status (Caused by NewConnectionError('<urllib3.connection.HTTPConnection object at 0x79f37b2bd280>: Failed to establish a new connection: [Errno 111] Connection refused'))

During handling of the above exception, another exception occurred:

Traceback (most recent call last):
  File "/home/airflow/.local/lib/python3.8/site-packages/airflow/decorators/base.py", line 221, in execute
    return_value = super().execute(context)
  File "/home/airflow/.local/lib/python3.8/site-packages/airflow/operators/python.py", line 192, in execute
    return_value = self.execute_callable()
  File "/home/airflow/.local/lib/python3.8/site-packages/airflow/operators/python.py", line 209, in execute_callable
    return self.python_callable(*self.op_args, **self.op_kwargs)
  File "/opt/airflow/dags/app.py", line 231, in transform_using_nifi
    response = requests.put(
  File "/home/airflow/.local/lib/python3.8/site-packages/requests/api.py", line 130, in put
    return request("put", url, data=data, **kwargs)
  File "/home/airflow/.local/lib/python3.8/site-packages/requests/api.py", line 59, in request
    return session.request(method=method, url=url, **kwargs)
  File "/home/airflow/.local/lib/python3.8/site-packages/requests/sessions.py", line 589, in request
    resp = self.send(prep, **send_kwargs)
  File "/home/airflow/.local/lib/python3.8/site-packages/requests/sessions.py", line 703, in send
    r = adapter.send(request, **kwargs)
  File "/home/airflow/.local/lib/python3.8/site-packages/requests/adapters.py", line 519, in send
    raise ConnectionError(e, request=request)
requests.exceptions.ConnectionError: HTTPConnectionPool(host='nifi', port=8080): Max retries exceeded with url: /nifi-api/flow/process-groups/21c8e227-0196-1000-55b1-efeba7bbe5dc/run-status (Caused by NewConnectionError('<urllib3.connection.HTTPConnection object at 0x79f37b2bd280>: Failed to establish a new connection: [Errno 111] Connection refused'))
[2025-04-10T22:46:30.826+0000] {taskinstance.py:1398} INFO - Marking task as UP_FOR_RETRY. dag_id=minio_pipeline_dag, task_id=transform_using_nifi, execution_date=20250410T224619, start_date=20250410T224630, end_date=20250410T224630
[2025-04-10T22:46:30.835+0000] {standard_task_runner.py:104} ERROR - Failed to execute job 17 for task transform_using_nifi (HTTPConnectionPool(host='nifi', port=8080): Max retries exceeded with url: /nifi-api/flow/process-groups/21c8e227-0196-1000-55b1-efeba7bbe5dc/run-status (Caused by NewConnectionError('<urllib3.connection.HTTPConnection object at 0x79f37b2bd280>: Failed to establish a new connection: [Errno 111] Connection refused')); 413)
[2025-04-10T22:46:30.848+0000] {local_task_job_runner.py:228} INFO - Task exited with return code 1
[2025-04-10T22:46:30.865+0000] {taskinstance.py:2776} INFO - 0 downstream tasks scheduled from follow-on schedule check
